<?xml version="1.0"?>
<sdf version="1.4">
<model name="door:door">
<pose>0 0 0 0 0 0</pose>
<static>false</static>


<link name="door:door-body">
<pose>0.0 0.49000000000000005 1.0 0.0 -0.0 0.0</pose>
<inertial>
<mass>1.0</mass>
<inertia> 
<ixx>0.4069</ixx>
<ixy>0.0</ixy>
<ixz>0.0</ixz>
<iyy>0.3322</iyy> 
<iyz>0.0</iyz>
<izz>0.0751</izz>
</inertia>
</inertial>
<collision name="collision">
<geometry>
<box>
<size>0.05 0.93 1.98</size>
</box>
</geometry>
</collision>
<visual name="visual">
<geometry>
<box>
<size>0.05 0.93 1.98</size>
</box>
</geometry><material><script><name>Gazebo/DarkYellow</name></script></material></visual>
</link>


<joint type="revolute" name="door:joint-door-hinge">
<pose frame="door:door-hinge">-0.025 0.025 0.995 0.0 -0.0 0.0</pose>
<child>door:door-body</child>
<parent>door:door-hinge</parent>
<axis>
<xyz>0 0 1</xyz>

<limit>
<lower>0.0</lower>
<upper>2.0</upper>
</limit>

</axis>
</joint>

</model>
</sdf>